Workbook

Sheet Project Overview
B2: E-Commerce Sales & Customer Analytics
B5: Portfolio project using a simulated 1,000-order e-commerce dataset to analyze revenue, profitability, customer behavior, product performance, regional trends, and acquisition channels.
B8: Section | C8: What it demonstrates | D8: Portfolio value
B9: Dashboard | C9: Executive KPIs and visual trends | D9: Communicating insights clearly
B10: Analysis | C10: Monthly, category, region, channel and customer-segment analysis | D10: Business analytics
B11: SQL Queries | C11: SQL used to answer practical business questions | D11: SQL proficiency
B12: Raw Data | C12: 1,000 simulated order-level records | D12: Data structure / analysis workflow
B13: Dataset Note | C13: All data is simulated for portfolio purposes | D13: Safe to publish publicly
B16: BUSINESS QUESTIONS
B18: 1. How did revenue and profit change throughout the year?
B19: 2. Which product categories generated the most revenue and profit?
B20: 3. Which regions and acquisition channels performed best?
B21: 4. How do new and returning customers differ in revenue contribution?
B22: 5. Which products combine strong sales with healthy margins?
B23: 6. What actions could management take based on the results?
B26: SKILLS
B28: SQL | C28: Excel | D28: Data Analysis | E28: Dashboarding | F28: Customer Analytics | G28: Business Insights

Sheet Dashboard
B2: E-Commerce Executive Dashboard
B4: Business question: What drives revenue and profit, which customers/channels matter most, and where should management focus?
B5: TOTAL REVENUE | E5: TOTAL PROFIT | H5: ORDERS | K5: AVG ORDER VALUE
B6: =SUM('Raw Data'!L2:L1001) -> 65062.466 | E6: =SUM('Raw Data'!N2:N1001) -> 34346.966 | H6: =COUNTA('Raw Data'!A2:A1001) -> 1000 | K6: =B6/H6 -> 65.062466
A40: Month | B40: Revenue ($) | C40: Profit ($) | D40: Orders | F40: Category | G40: Revenue ($) | H40: Profit ($) | I40: Profit Margin | K40: Region | L40: Revenue ($) | M40: Profit ($) | N40: Orders | P40: Channel | Q40: Revenue ($) | R40: Profit ($) | S40: Orders
A41: 45658 | B41: =SUMIFS('Raw Data'!$L$2:$L$1001,'Raw Data'!$B$2:$B$1001,">="&A41,'Raw Data'!$B$2:$B$1001,"<"&EDATE(A41,1)) -> 4946.5405 | C41: =SUMIFS('Raw Data'!$N$2:$N$1001,'Raw Data'!$B$2:$B$1001,">="&A41,'Raw Data'!$B$2:$B$1001,"<"&EDATE(A41,1)) -> 2664.0405 | D41: =COUNTIFS('Raw Data'!$B$2:$B$1001,">="&A41,'Raw Data'!$B$2:$B$1001,"<"&EDATE(A41,1)) -> 79 | F41: Electronics | G41: =SUMIF('Raw Data'!$H$2:$H$1001,F41,'Raw Data'!$L$2:$L$1001) -> 28041.416 | H41: =SUMIF('Raw Data'!$H$2:$H$1001,F41,'Raw Data'!$N$2:$N$1001) -> 13539.416 | I41: =H41/G41 -> 0.48283639 | K41: Northeast | L41: =SUMIF('Raw Data'!$E$2:$E$1001,K41,'Raw Data'!$L$2:$L$1001) -> 16755.14 | M41: =SUMIF('Raw Data'!$E$2:$E$1001,K41,'Raw Data'!$N$2:$N$1001) -> 8728.1405 | N41: =COUNTIF('Raw Data'!$E$2:$E$1001,K41) -> 240 | P41: Organic Search | Q41: =SUMIF('Raw Data'!$F$2:$F$1001,P41,'Raw Data'!$L$2:$L$1001) -> 13080.702 | R41: =SUMIF('Raw Data'!$F$2:$F$1001,P41,'Raw Data'!$N$2:$N$1001) -> 6939.2025 | S41: =COUNTIF('Raw Data'!$F$2:$F$1001,P41) -> 203
A42: 45689 | B42: =SUMIFS('Raw Data'!$L$2:$L$1001,'Raw Data'!$B$2:$B$1001,">="&A42,'Raw Data'!$B$2:$B$1001,"<"&EDATE(A42,1)) -> 5050.223 | C42: =SUMIFS('Raw Data'!$N$2:$N$1001,'Raw Data'!$B$2:$B$1001,">="&A42,'Raw Data'!$B$2:$B$1001,"<"&EDATE(A42,1)) -> 2609.223 | D42: =COUNTIFS('Raw Data'!$B$2:$B$1001,">="&A42,'Raw Data'!$B$2:$B$1001,"<"&EDATE(A42,1)) -> 79 | F42: Home & Office | G42: =SUMIF('Raw Data'!$H$2:$H$1001,F42,'Raw Data'!$L$2:$L$1001) -> 14052.1 | H42: =SUMIF('Raw Data'!$H$2:$H$1001,F42,'Raw Data'!$N$2:$N$1001) -> 7819.1 | I42: =H42/G42 -> 0.5564364 | K42: South | L42: =SUMIF('Raw Data'!$E$2:$E$1001,K42,'Raw Data'!$L$2:$L$1001) -> 15882.524 | M42: =SUMIF('Raw Data'!$E$2:$E$1001,K42,'Raw Data'!$N$2:$N$1001) -> 8459.524 | N42: =COUNTIF('Raw Data'!$E$2:$E$1001,K42) -> 257 | P42: Paid Social | Q42: =SUMIF('Raw Data'!$F$2:$F$1001,P42,'Raw Data'!$L$2:$L$1001) -> 12709.87 | R42: =SUMIF('Raw Data'!$F$2:$F$1001,P42,'Raw Data'!$N$2:$N$1001) -> 6698.3705 | S42: =COUNTIF('Raw Data'!$F$2:$F$1001,P42) -> 197
A43: 45717 | B43: =SUMIFS('Raw Data'!$L$2:$L$1001,'Raw Data'!$B$2:$B$1001,">="&A43,'Raw Data'!$B$2:$B$1001,"<"&EDATE(A43,1)) -> 6873.9445 | C43: =SUMIFS('Raw Data'!$N$2:$N$1001,'Raw Data'!$B$2:$B$1001,">="&A43,'Raw Data'!$B$2:$B$1001,"<"&EDATE(A43,1)) -> 3572.4445 | D43: =COUNTIFS('Raw Data'!$B$2:$B$1001,">="&A43,'Raw Data'!$B$2:$B$1001,"<"&EDATE(A43,1)) -> 91 | F43: Lifestyle | G43: =SUMIF('Raw Data'!$H$2:$H$1001,F43,'Raw Data'!$L$2:$L$1001) -> 14169.35 | H43: =SUMIF('Raw Data'!$H$2:$H$1001,F43,'Raw Data'!$N$2:$N$1001) -> 7698.35 | I43: =H43/G43 -> 0.54331003 | K43: Midwest | L43: =SUMIF('Raw Data'!$E$2:$E$1001,K43,'Raw Data'!$L$2:$L$1001) -> 15433.042 | M43: =SUMIF('Raw Data'!$E$2:$E$1001,K43,'Raw Data'!$N$2:$N$1001) -> 8168.5425 | N43: =COUNTIF('Raw Data'!$E$2:$E$1001,K43) -> 249 | P43: Email | Q43: =SUMIF('Raw Data'!$F$2:$F$1001,P43,'Raw Data'!$L$2:$L$1001) -> 13794.719 | R43: =SUMIF('Raw Data'!$F$2:$F$1001,P43,'Raw Data'!$N$2:$N$1001) -> 7300.2195 | S43: =COUNTIF('Raw Data'!$F$2:$F$1001,P43) -> 208
A44: 45748 | B44: =SUMIFS('Raw Data'!$L$2:$L$1001,'Raw Data'!$B$2:$B$1001,">="&A44,'Raw Data'!$B$2:$B$1001,"<"&EDATE(A44,1)) -> 5542.334 | C44: =SUMIFS('Raw Data'!$N$2:$N$1001,'Raw Data'!$B$2:$B$1001,">="&A44,'Raw Data'!$B$2:$B$1001,"<"&EDATE(A44,1)) -> 2938.334 | D44: =COUNTIFS('Raw Data'!$B$2:$B$1001,">="&A44,'Raw Data'!$B$2:$B$1001,"<"&EDATE(A44,1)) -> 81 | F44: Fitness | G44: =SUMIF('Raw Data'!$H$2:$H$1001,F44,'Raw Data'!$L$2:$L$1001) -> 8799.6 | H44: =SUMIF('Raw Data'!$H$2:$H$1001,F44,'Raw Data'!$N$2:$N$1001) -> 5290.1 | I44: =H44/G44 -> 0.60117505 | K44: West | L44: =SUMIF('Raw Data'!$E$2:$E$1001,K44,'Raw Data'!$L$2:$L$1001) -> 16991.759 | M44: =SUMIF('Raw Data'!$E$2:$E$1001,K44,'Raw Data'!$N$2:$N$1001) -> 8990.759 | N44: =COUNTIF('Raw Data'!$E$2:$E$1001,K44) -> 254 | P44: Direct | Q44: =SUMIF('Raw Data'!$F$2:$F$1001,P44,'Raw Data'!$L$2:$L$1001) -> 13260.229 | R44: =SUMIF('Raw Data'!$F$2:$F$1001,P44,'Raw Data'!$N$2:$N$1001) -> 7001.2295 | S44: =COUNTIF('Raw Data'!$F$2:$F$1001,P44) -> 220
A45: 45778 | B45: =SUMIFS('Raw Data'!$L$2:$L$1001,'Raw Data'!$B$2:$B$1001,">="&A45,'Raw Data'!$B$2:$B$1001,"<"&EDATE(A45,1)) -> 5170.1145 | C45: =SUMIFS('Raw Data'!$N$2:$N$1001,'Raw Data'!$B$2:$B$1001,">="&A45,'Raw Data'!$B$2:$B$1001,"<"&EDATE(A45,1)) -> 2712.1145 | D45: =COUNTIFS('Raw Data'!$B$2:$B$1001,">="&A45,'Raw Data'!$B$2:$B$1001,"<"&EDATE(A45,1)) -> 83 | P45: Referral | Q45: =SUMIF('Raw Data'!$F$2:$F$1001,P45,'Raw Data'!$L$2:$L$1001) -> 12216.944 | R45: =SUMIF('Raw Data'!$F$2:$F$1001,P45,'Raw Data'!$N$2:$N$1001) -> 6407.944 | S45: =COUNTIF('Raw Data'!$F$2:$F$1001,P45) -> 172
A46: 45809 | B46: =SUMIFS('Raw Data'!$L$2:$L$1001,'Raw Data'!$B$2:$B$1001,">="&A46,'Raw Data'!$B$2:$B$1001,"<"&EDATE(A46,1)) -> 4328.1935 | C46: =SUMIFS('Raw Data'!$N$2:$N$1001,'Raw Data'!$B$2:$B$1001,">="&A46,'Raw Data'!$B$2:$B$1001,"<"&EDATE(A46,1)) -> 2299.6935 | D46: =COUNTIFS('Raw Data'!$B$2:$B$1001,">="&A46,'Raw Data'!$B$2:$B$1001,"<"&EDATE(A46,1)) -> 71
A47: 45839 | B47: =SUMIFS('Raw Data'!$L$2:$L$1001,'Raw Data'!$B$2:$B$1001,">="&A47,'Raw Data'!$B$2:$B$1001,"<"&EDATE(A47,1)) -> 5828.3065 | C47: =SUMIFS('Raw Data'!$N$2:$N$1001,'Raw Data'!$B$2:$B$1001,">="&A47,'Raw Data'!$B$2:$B$1001,"<"&EDATE(A47,1)) -> 3010.8065 | D47: =COUNTIFS('Raw Data'!$B$2:$B$1001,">="&A47,'Raw Data'!$B$2:$B$1001,"<"&EDATE(A47,1)) -> 83
A48: 45870 | B48: =SUMIFS('Raw Data'!$L$2:$L$1001,'Raw Data'!$B$2:$B$1001,">="&A48,'Raw Data'!$B$2:$B$1001,"<"&EDATE(A48,1)) -> 5944.6695 | C48: =SUMIFS('Raw Data'!$N$2:$N$1001,'Raw Data'!$B$2:$B$1001,">="&A48,'Raw Data'!$B$2:$B$1001,"<"&EDATE(A48,1)) -> 3147.1695 | D48: =COUNTIFS('Raw Data'!$B$2:$B$1001,">="&A48,'Raw Data'!$B$2:$B$1001,"<"&EDATE(A48,1)) -> 88
A49: 45901 | B49: =SUMIFS('Raw Data'!$L$2:$L$1001,'Raw Data'!$B$2:$B$1001,">="&A49,'Raw Data'!$B$2:$B$1001,"<"&EDATE(A49,1)) -> 4221.321 | C49: =SUMIFS('Raw Data'!$N$2:$N$1001,'Raw Data'!$B$2:$B$1001,">="&A49,'Raw Data'!$B$2:$B$1001,"<"&EDATE(A49,1)) -> 2284.321 | D49: =COUNTIFS('Raw Data'!$B$2:$B$1001,">="&A49,'Raw Data'!$B$2:$B$1001,"<"&EDATE(A49,1)) -> 76
A50: 45931 | B50: =SUMIFS('Raw Data'!$L$2:$L$1001,'Raw Data'!$B$2:$B$1001,">="&A50,'Raw Data'!$B$2:$B$1001,"<"&EDATE(A50,1)) -> 5456.747 | C50: =SUMIFS('Raw Data'!$N$2:$N$1001,'Raw Data'!$B$2:$B$1001,">="&A50,'Raw Data'!$B$2:$B$1001,"<"&EDATE(A50,1)) -> 2892.247 | D50: =COUNTIFS('Raw Data'!$B$2:$B$1001,">="&A50,'Raw Data'!$B$2:$B$1001,"<"&EDATE(A50,1)) -> 93
A51: 45962 | B51: =SUMIFS('Raw Data'!$L$2:$L$1001,'Raw Data'!$B$2:$B$1001,">="&A51,'Raw Data'!$B$2:$B$1001,"<"&EDATE(A51,1)) -> 6109.571 | C51: =SUMIFS('Raw Data'!$N$2:$N$1001,'Raw Data'!$B$2:$B$1001,">="&A51,'Raw Data'!$B$2:$B$1001,"<"&EDATE(A51,1)) -> 3206.571 | D51: =COUNTIFS('Raw Data'!$B$2:$B$1001,">="&A51,'Raw Data'!$B$2:$B$1001,"<"&EDATE(A51,1)) -> 87
A52: 45992 | B52: =SUMIFS('Raw Data'!$L$2:$L$1001,'Raw Data'!$B$2:$B$1001,">="&A52,'Raw Data'!$B$2:$B$1001,"<"&EDATE(A52,1)) -> 5590.501 | C52: =SUMIFS('Raw Data'!$N$2:$N$1001,'Raw Data'!$B$2:$B$1001,">="&A52,'Raw Data'!$B$2:$B$1001,"<"&EDATE(A52,1)) -> 3010.001 | D52: =COUNTIFS('Raw Data'!$B$2:$B$1001,">="&A52,'Raw Data'!$B$2:$B$1001,"<"&EDATE(A52,1)) -> 89

Sheet Analysis
A1: E-Commerce Business Analysis | What is driving revenue and profit?
A4: Objective: identify the main drivers of sales and profitability, evaluate customer and channel performance, and translate the findings into practical management recommendations.
A7: 1 | EXECUTIVE PERFORMANCE
A9: Metric | B9: Result | C9: Interpretation | E9: Month | F9: Revenue ($) | G9: Profit ($) | H9: Orders
A10: Total Revenue | B10: =SUM('Raw Data'!L2:L1001) -> 65062.466 | C10: Overall sales generated during the simulated year. | E10: 45658 | F10: =SUMIFS('Raw Data'!$L$2:$L$1001,'Raw Data'!$B$2:$B$1001,">="&E10,'Raw Data'!$B$2:$B$1001,"<"&EDATE(E10,1)) -> 4946.5405 | G10: =SUMIFS('Raw Data'!$N$2:$N$1001,'Raw Data'!$B$2:$B$1001,">="&E10,'Raw Data'!$B$2:$B$1001,"<"&EDATE(E10,1)) -> 2664.0405 | H10: =COUNTIFS('Raw Data'!$B$2:$B$1001,">="&E10,'Raw Data'!$B$2:$B$1001,"<"&EDATE(E10,1)) -> 79
A11: Total Profit | B11: =SUM('Raw Data'!N2:N1001) -> 34346.966 | C11: Gross profit after product-level COGS. | E11: 45689 | F11: =SUMIFS('Raw Data'!$L$2:$L$1001,'Raw Data'!$B$2:$B$1001,">="&E11,'Raw Data'!$B$2:$B$1001,"<"&EDATE(E11,1)) -> 5050.223 | G11: =SUMIFS('Raw Data'!$N$2:$N$1001,'Raw Data'!$B$2:$B$1001,">="&E11,'Raw Data'!$B$2:$B$1001,"<"&EDATE(E11,1)) -> 2609.223 | H11: =COUNTIFS('Raw Data'!$B$2:$B$1001,">="&E11,'Raw Data'!$B$2:$B$1001,"<"&EDATE(E11,1)) -> 79
A12: Profit Margin | B12: =B11/B10 -> 0.52790753 | C12: Measures how efficiently revenue converts into profit. | E12: 45717 | F12: =SUMIFS('Raw Data'!$L$2:$L$1001,'Raw Data'!$B$2:$B$1001,">="&E12,'Raw Data'!$B$2:$B$1001,"<"&EDATE(E12,1)) -> 6873.9445 | G12: =SUMIFS('Raw Data'!$N$2:$N$1001,'Raw Data'!$B$2:$B$1001,">="&E12,'Raw Data'!$B$2:$B$1001,"<"&EDATE(E12,1)) -> 3572.4445 | H12: =COUNTIFS('Raw Data'!$B$2:$B$1001,">="&E12,'Raw Data'!$B$2:$B$1001,"<"&EDATE(E12,1)) -> 91
A13: Orders | B13: =COUNTA('Raw Data'!A2:A1001) -> 1000 | C13: Total order volume. | E13: 45748 | F13: =SUMIFS('Raw Data'!$L$2:$L$1001,'Raw Data'!$B$2:$B$1001,">="&E13,'Raw Data'!$B$2:$B$1001,"<"&EDATE(E13,1)) -> 5542.334 | G13: =SUMIFS('Raw Data'!$N$2:$N$1001,'Raw Data'!$B$2:$B$1001,">="&E13,'Raw Data'!$B$2:$B$1001,"<"&EDATE(E13,1)) -> 2938.334 | H13: =COUNTIFS('Raw Data'!$B$2:$B$1001,">="&E13,'Raw Data'!$B$2:$B$1001,"<"&EDATE(E13,1)) -> 81
A14: Average Order Value | B14: =B10/B13 -> 65.062466 | C14: Average revenue generated per order. | E14: 45778 | F14: =SUMIFS('Raw Data'!$L$2:$L$1001,'Raw Data'!$B$2:$B$1001,">="&E14,'Raw Data'!$B$2:$B$1001,"<"&EDATE(E14,1)) -> 5170.1145 | G14: =SUMIFS('Raw Data'!$N$2:$N$1001,'Raw Data'!$B$2:$B$1001,">="&E14,'Raw Data'!$B$2:$B$1001,"<"&EDATE(E14,1)) -> 2712.1145 | H14: =COUNTIFS('Raw Data'!$B$2:$B$1001,">="&E14,'Raw Data'!$B$2:$B$1001,"<"&EDATE(E14,1)) -> 83
E15: 45809 | F15: =SUMIFS('Raw Data'!$L$2:$L$1001,'Raw Data'!$B$2:$B$1001,">="&E15,'Raw Data'!$B$2:$B$1001,"<"&EDATE(E15,1)) -> 4328.1935 | G15: =SUMIFS('Raw Data'!$N$2:$N$1001,'Raw Data'!$B$2:$B$1001,">="&E15,'Raw Data'!$B$2:$B$1001,"<"&EDATE(E15,1)) -> 2299.6935 | H15: =COUNTIFS('Raw Data'!$B$2:$B$1001,">="&E15,'Raw Data'!$B$2:$B$1001,"<"&EDATE(E15,1)) -> 71
E16: 45839 | F16: =SUMIFS('Raw Data'!$L$2:$L$1001,'Raw Data'!$B$2:$B$1001,">="&E16,'Raw Data'!$B$2:$B$1001,"<"&EDATE(E16,1)) -> 5828.3065 | G16: =SUMIFS('Raw Data'!$N$2:$N$1001,'Raw Data'!$B$2:$B$1001,">="&E16,'Raw Data'!$B$2:$B$1001,"<"&EDATE(E16,1)) -> 3010.8065 | H16: =COUNTIFS('Raw Data'!$B$2:$B$1001,">="&E16,'Raw Data'!$B$2:$B$1001,"<"&EDATE(E16,1)) -> 83
E17: 45870 | F17: =SUMIFS('Raw Data'!$L$2:$L$1001,'Raw Data'!$B$2:$B$1001,">="&E17,'Raw Data'!$B$2:$B$1001,"<"&EDATE(E17,1)) -> 5944.6695 | G17: =SUMIFS('Raw Data'!$N$2:$N$1001,'Raw Data'!$B$2:$B$1001,">="&E17,'Raw Data'!$B$2:$B$1001,"<"&EDATE(E17,1)) -> 3147.1695 | H17: =COUNTIFS('Raw Data'!$B$2:$B$1001,">="&E17,'Raw Data'!$B$2:$B$1001,"<"&EDATE(E17,1)) -> 88
E18: 45901 | F18: =SUMIFS('Raw Data'!$L$2:$L$1001,'Raw Data'!$B$2:$B$1001,">="&E18,'Raw Data'!$B$2:$B$1001,"<"&EDATE(E18,1)) -> 4221.321 | G18: =SUMIFS('Raw Data'!$N$2:$N$1001,'Raw Data'!$B$2:$B$1001,">="&E18,'Raw Data'!$B$2:$B$1001,"<"&EDATE(E18,1)) -> 2284.321 | H18: =COUNTIFS('Raw Data'!$B$2:$B$1001,">="&E18,'Raw Data'!$B$2:$B$1001,"<"&EDATE(E18,1)) -> 76
E19: 45931 | F19: =SUMIFS('Raw Data'!$L$2:$L$1001,'Raw Data'!$B$2:$B$1001,">="&E19,'Raw Data'!$B$2:$B$1001,"<"&EDATE(E19,1)) -> 5456.747 | G19: =SUMIFS('Raw Data'!$N$2:$N$1001,'Raw Data'!$B$2:$B$1001,">="&E19,'Raw Data'!$B$2:$B$1001,"<"&EDATE(E19,1)) -> 2892.247 | H19: =COUNTIFS('Raw Data'!$B$2:$B$1001,">="&E19,'Raw Data'!$B$2:$B$1001,"<"&EDATE(E19,1)) -> 93
E20: 45962 | F20: =SUMIFS('Raw Data'!$L$2:$L$1001,'Raw Data'!$B$2:$B$1001,">="&E20,'Raw Data'!$B$2:$B$1001,"<"&EDATE(E20,1)) -> 6109.571 | G20: =SUMIFS('Raw Data'!$N$2:$N$1001,'Raw Data'!$B$2:$B$1001,">="&E20,'Raw Data'!$B$2:$B$1001,"<"&EDATE(E20,1)) -> 3206.571 | H20: =COUNTIFS('Raw Data'!$B$2:$B$1001,">="&E20,'Raw Data'!$B$2:$B$1001,"<"&EDATE(E20,1)) -> 87
E21: 45992 | F21: =SUMIFS('Raw Data'!$L$2:$L$1001,'Raw Data'!$B$2:$B$1001,">="&E21,'Raw Data'!$B$2:$B$1001,"<"&EDATE(E21,1)) -> 5590.501 | G21: =SUMIFS('Raw Data'!$N$2:$N$1001,'Raw Data'!$B$2:$B$1001,">="&E21,'Raw Data'!$B$2:$B$1001,"<"&EDATE(E21,1)) -> 3010.001 | H21: =COUNTIFS('Raw Data'!$B$2:$B$1001,">="&E21,'Raw Data'!$B$2:$B$1001,"<"&EDATE(E21,1)) -> 89
A24: 2 | CUSTOMER & ACQUISITION ANALYSIS
A26: Customer Segment | B26: Revenue ($) | C26: Profit ($) | D26: Orders | E26: AOV ($) | G26: Channel | H26: Revenue ($) | I26: Profit ($) | J26: Orders | K26: AOV ($)
A27: New | B27: =SUMIF('Raw Data'!$D$2:$D$1001,A27,'Raw Data'!$L$2:$L$1001) -> 38525.303 | C27: =SUMIF('Raw Data'!$D$2:$D$1001,A27,'Raw Data'!$N$2:$N$1001) -> 20414.803 | D27: =COUNTIF('Raw Data'!$D$2:$D$1001,A27) -> 587 | E27: =B27/D27 -> 65.63084 | G27: Organic Search | H27: =SUMIF('Raw Data'!$F$2:$F$1001,G27,'Raw Data'!$L$2:$L$1001) -> 13080.702 | I27: =SUMIF('Raw Data'!$F$2:$F$1001,G27,'Raw Data'!$N$2:$N$1001) -> 6939.2025 | J27: =COUNTIF('Raw Data'!$F$2:$F$1001,G27) -> 203 | K27: =H27/J27 -> 64.436958
A28: Returning | B28: =SUMIF('Raw Data'!$D$2:$D$1001,A28,'Raw Data'!$L$2:$L$1001) -> 26537.163 | C28: =SUMIF('Raw Data'!$D$2:$D$1001,A28,'Raw Data'!$N$2:$N$1001) -> 13932.163 | D28: =COUNTIF('Raw Data'!$D$2:$D$1001,A28) -> 413 | E28: =B28/D28 -> 64.254632 | G28: Paid Social | H28: =SUMIF('Raw Data'!$F$2:$F$1001,G28,'Raw Data'!$L$2:$L$1001) -> 12709.87 | I28: =SUMIF('Raw Data'!$F$2:$F$1001,G28,'Raw Data'!$N$2:$N$1001) -> 6698.3705 | J28: =COUNTIF('Raw Data'!$F$2:$F$1001,G28) -> 197 | K28: =H28/J28 -> 64.517109
G29: Email | H29: =SUMIF('Raw Data'!$F$2:$F$1001,G29,'Raw Data'!$L$2:$L$1001) -> 13794.719 | I29: =SUMIF('Raw Data'!$F$2:$F$1001,G29,'Raw Data'!$N$2:$N$1001) -> 7300.2195 | J29: =COUNTIF('Raw Data'!$F$2:$F$1001,G29) -> 208 | K29: =H29/J29 -> 66.320767
G30: Direct | H30: =SUMIF('Raw Data'!$F$2:$F$1001,G30,'Raw Data'!$L$2:$L$1001) -> 13260.229 | I30: =SUMIF('Raw Data'!$F$2:$F$1001,G30,'Raw Data'!$N$2:$N$1001) -> 7001.2295 | J30: =COUNTIF('Raw Data'!$F$2:$F$1001,G30) -> 220 | K30: =H30/J30 -> 60.27377
G31: Referral | H31: =SUMIF('Raw Data'!$F$2:$F$1001,G31,'Raw Data'!$L$2:$L$1001) -> 12216.944 | I31: =SUMIF('Raw Data'!$F$2:$F$1001,G31,'Raw Data'!$N$2:$N$1001) -> 6407.944 | J31: =COUNTIF('Raw Data'!$F$2:$F$1001,G31) -> 172 | K31: =H31/J31 -> 71.028744
A34: 3 | PRODUCT & CATEGORY ECONOMICS
A36: Category | B36: Revenue ($) | C36: Profit ($) | D36: Margin | E36: Revenue Share | G36: Product | H36: Units | I36: Revenue ($) | J36: Profit ($) | K36: Margin | L36: Revenue Share
A37: Electronics | B37: =SUMIF('Raw Data'!$H$2:$H$1001,A37,'Raw Data'!$L$2:$L$1001) -> 28041.416 | C37: =SUMIF('Raw Data'!$H$2:$H$1001,A37,'Raw Data'!$N$2:$N$1001) -> 13539.416 | D37: =C37/B37 -> 0.48283639 | E37: =B37/$B$10 -> 0.43099221 | G37: Wireless Earbuds | H37: =SUMIF('Raw Data'!$G$2:$G$1001,G37,'Raw Data'!$I$2:$I$1001) -> 159 | I37: =SUMIF('Raw Data'!$G$2:$G$1001,G37,'Raw Data'!$L$2:$L$1001) -> 8944.509 | J37: =SUMIF('Raw Data'!$G$2:$G$1001,G37,'Raw Data'!$N$2:$N$1001) -> 4492.509 | K37: =J37/I37 -> 0.50226446 | L37: =I37/$B$10 -> 0.13747571
A38: Home & Office | B38: =SUMIF('Raw Data'!$H$2:$H$1001,A38,'Raw Data'!$L$2:$L$1001) -> 14052.1 | C38: =SUMIF('Raw Data'!$H$2:$H$1001,A38,'Raw Data'!$N$2:$N$1001) -> 7819.1 | D38: =C38/B38 -> 0.5564364 | E38: =B38/$B$10 -> 0.2159786 | G38: Portable Charger | H38: =SUMIF('Raw Data'!$G$2:$G$1001,G38,'Raw Data'!$I$2:$I$1001) -> 125 | I38: =SUMIF('Raw Data'!$G$2:$G$1001,G38,'Raw Data'!$L$2:$L$1001) -> 4127.0705 | J38: =SUMIF('Raw Data'!$G$2:$G$1001,G38,'Raw Data'!$N$2:$N$1001) -> 2127.0705 | K38: =J38/I38 -> 0.51539476 | L38: =I38/$B$10 -> 0.063432433
A39: Lifestyle | B39: =SUMIF('Raw Data'!$H$2:$H$1001,A39,'Raw Data'!$L$2:$L$1001) -> 14169.35 | C39: =SUMIF('Raw Data'!$H$2:$H$1001,A39,'Raw Data'!$N$2:$N$1001) -> 7698.35 | D39: =C39/B39 -> 0.54331003 | E39: =B39/$B$10 -> 0.21778071 | G39: Mechanical Keyboard | H39: =SUMIF('Raw Data'!$G$2:$G$1001,G39,'Raw Data'!$I$2:$I$1001) -> 175 | I39: =SUMIF('Raw Data'!$G$2:$G$1001,G39,'Raw Data'!$L$2:$L$1001) -> 14969.836 | J39: =SUMIF('Raw Data'!$G$2:$G$1001,G39,'Raw Data'!$N$2:$N$1001) -> 6919.8365 | K39: =J39/I39 -> 0.46225198 | L39: =I39/$B$10 -> 0.23008406
A40: Fitness | B40: =SUMIF('Raw Data'!$H$2:$H$1001,A40,'Raw Data'!$L$2:$L$1001) -> 8799.6 | C40: =SUMIF('Raw Data'!$H$2:$H$1001,A40,'Raw Data'!$N$2:$N$1001) -> 5290.1 | D40: =C40/B40 -> 0.60117505 | E40: =B40/$B$10 -> 0.13524849 | G40: Desk Lamp | H40: =SUMIF('Raw Data'!$G$2:$G$1001,G40,'Raw Data'!$I$2:$I$1001) -> 149 | I40: =SUMIF('Raw Data'!$G$2:$G$1001,G40,'Raw Data'!$L$2:$L$1001) -> 5825.4 | J40: =SUMIF('Raw Data'!$G$2:$G$1001,G40,'Raw Data'!$N$2:$N$1001) -> 2994.4 | K40: =J40/I40 -> 0.51402479 | L40: =I40/$B$10 -> 0.089535493
G41: Laptop Stand | H41: =SUMIF('Raw Data'!$G$2:$G$1001,G41,'Raw Data'!$I$2:$I$1001) -> 138 | I41: =SUMIF('Raw Data'!$G$2:$G$1001,G41,'Raw Data'!$L$2:$L$1001) -> 4989.4 | J41: =SUMIF('Raw Data'!$G$2:$G$1001,G41,'Raw Data'!$N$2:$N$1001) -> 2643.4 | K41: =J41/I41 -> 0.52980318 | L41: =I41/$B$10 -> 0.076686303
G42: Insulated Bottle | H42: =SUMIF('Raw Data'!$G$2:$G$1001,G42,'Raw Data'!$I$2:$I$1001) -> 143 | I42: =SUMIF('Raw Data'!$G$2:$G$1001,G42,'Raw Data'!$L$2:$L$1001) -> 3925.15 | J42: =SUMIF('Raw Data'!$G$2:$G$1001,G42,'Raw Data'!$N$2:$N$1001) -> 2352.15 | K42: =J42/I42 -> 0.59925098 | L42: =I42/$B$10 -> 0.060328946
G43: Yoga Mat | H43: =SUMIF('Raw Data'!$G$2:$G$1001,G43,'Raw Data'!$I$2:$I$1001) -> 158 | I43: =SUMIF('Raw Data'!$G$2:$G$1001,G43,'Raw Data'!$L$2:$L$1001) -> 5190.5 | J43: =SUMIF('Raw Data'!$G$2:$G$1001,G43,'Raw Data'!$N$2:$N$1001) -> 2978.5 | K43: =J43/I43 -> 0.57383682 | L43: =I43/$B$10 -> 0.079777179
G44: Resistance Bands | H44: =SUMIF('Raw Data'!$G$2:$G$1001,G44,'Raw Data'!$I$2:$I$1001) -> 173 | I44: =SUMIF('Raw Data'!$G$2:$G$1001,G44,'Raw Data'!$L$2:$L$1001) -> 3609.1 | J44: =SUMIF('Raw Data'!$G$2:$G$1001,G44,'Raw Data'!$N$2:$N$1001) -> 2311.6 | K44: =J44/I44 -> 0.64049209 | L44: =I44/$B$10 -> 0.055471307
G45: Travel Backpack | H45: =SUMIF('Raw Data'!$G$2:$G$1001,G45,'Raw Data'!$I$2:$I$1001) -> 158 | I45: =SUMIF('Raw Data'!$G$2:$G$1001,G45,'Raw Data'!$L$2:$L$1001) -> 10244.2 | J45: =SUMIF('Raw Data'!$G$2:$G$1001,G45,'Raw Data'!$N$2:$N$1001) -> 5346.2 | K45: =J45/I45 -> 0.52187579 | L45: =I45/$B$10 -> 0.15745176
G46: Notebook Set | H46: =SUMIF('Raw Data'!$G$2:$G$1001,G46,'Raw Data'!$I$2:$I$1001) -> 192 | I46: =SUMIF('Raw Data'!$G$2:$G$1001,G46,'Raw Data'!$L$2:$L$1001) -> 3237.3 | J46: =SUMIF('Raw Data'!$G$2:$G$1001,G46,'Raw Data'!$N$2:$N$1001) -> 2181.3 | K46: =J46/I46 -> 0.67380224 | L46: =I46/$B$10 -> 0.049756798
A49: 4 | DISCOUNT IMPACT
A51: Discount | B51: Orders | C51: Revenue ($) | D51: Profit ($) | E51: Profit Margin | F51: AOV ($) | H51: KEY FINDINGS
A52: 0 | B52: =COUNTIF('Raw Data'!$K$2:$K$1001,A52) -> 458 | C52: =SUMIF('Raw Data'!$K$2:$K$1001,A52,'Raw Data'!$L$2:$L$1001) -> 31090 | D52: =SUMIF('Raw Data'!$K$2:$K$1001,A52,'Raw Data'!$N$2:$N$1001) -> 17243 | E52: =D52/C52 -> 0.55461563 | F52: =C52/B52 -> 67.882096 | H52: ="• "&INDEX(G37:G46,MATCH(MAX(I37:I46),I37:I46,0))&" is the highest-revenue product, generating "&TEXT(MAX(I37:I46),"$#,##0")&" in sales." -> • Mechanical Keyboard is the highest-revenue product, generating $14,970 in sales.
A53: 0.05 | B53: =COUNTIF('Raw Data'!$K$2:$K$1001,A53) -> 180 | C53: =SUMIF('Raw Data'!$K$2:$K$1001,A53,'Raw Data'!$L$2:$L$1001) -> 13514.662 | D53: =SUMIF('Raw Data'!$K$2:$K$1001,A53,'Raw Data'!$N$2:$N$1001) -> 7068.662 | E53: =D53/C53 -> 0.52303654 | F53: =C53/B53 -> 75.081456
A54: 0.1 | B54: =COUNTIF('Raw Data'!$K$2:$K$1001,A54) -> 193 | C54: =SUMIF('Raw Data'!$K$2:$K$1001,A54,'Raw Data'!$L$2:$L$1001) -> 11642.553 | D54: =SUMIF('Raw Data'!$K$2:$K$1001,A54,'Raw Data'!$N$2:$N$1001) -> 5887.553 | E54: =D54/C54 -> 0.50569261 | F54: =C54/B54 -> 60.324109 | H54: ="• "&INDEX(A37:A40,MATCH(MAX(D37:D40),D37:D40,0))&" has the strongest category profit margin at "&TEXT(MAX(D37:D40),"0.0%")&"." -> • Fitness has the strongest category profit margin at 60.1%.
...

Sheet SQL Queries
A1: SQL Business Analysis
A4: The queries below show how the same business questions could be answered in SQL. Table name: orders.
A7: 1. Monthly revenue and profit
A8: SELECT DATE_TRUNC('month', order_date) AS month, SUM(revenue) AS revenue, SUM(profit) AS profit, COUNT(DISTINCT order_id) AS orders FROM orders GROUP BY 1 ORDER BY 1;
A17: 2. Category performance
A18: SELECT category, SUM(revenue) AS revenue, SUM(profit) AS profit, SUM(profit) / NULLIF(SUM(revenue), 0) AS profit_margin FROM orders GROUP BY category ORDER BY revenue DESC;
A27: 3. Regional performance
A28: SELECT region, SUM(revenue) AS revenue, SUM(profit) AS profit, COUNT(DISTINCT order_id) AS orders FROM orders GROUP BY region ORDER BY revenue DESC;
A37: 4. New vs. returning customers
A38: SELECT customer_segment, COUNT(DISTINCT customer_id) AS customers, COUNT(DISTINCT order_id) AS orders, SUM(revenue) AS revenue, AVG(revenue) AS avg_order_value FROM orders GROUP BY customer_segment;
A47: 5. Acquisition-channel performance
A48: SELECT acquisition_channel, COUNT(DISTINCT order_id) AS orders, SUM(revenue) AS revenue, SUM(profit) AS profit FROM orders GROUP BY acquisition_channel ORDER BY revenue DESC;
... A58: SELECT product, category, SUM(quantity) AS units_sold, SUM(revenue) AS revenue, SUM(profit) AS profit FROM orders GROUP BY product, category ORDER BY profit DESC LIMIT 10;

Sheet Raw Data
A1: Order ID | B1: Order Date | C1: Customer ID | D1: Customer Segment | E1: Region | F1: Acquisition Channel | G1: Product | H1: Category | I1: Quantity | J1: Unit Price ($) | K1: Discount % | L1: Revenue ($) | M1: COGS ($) | N1: Profit ($)
A2: O00001 | B2: 45985 | C2: C0378 | D2: New | E2: Northeast | F2: Referral | G2: Portable Charger | H2: Electronics | I2: 1 | J2: 34.99 | K2: 0 | L2: 34.99 | M2: 16 | N2: 18.99
A3: O00002 | B3: 45702 | C3: C0259 | D3: New | E3: Northeast | F3: Referral | G3: Notebook Set | H3: Home & Office | I3: 1 | J3: 18 | K3: 0 | L3: 18 | M3: 5.5 | N3: 12.5
A4: O00003 | B4: 45759 | C4: C0004 | D4: New | E4: South | F4: Direct | G4: Travel Backpack | H4: Lifestyle | I4: 1 | J4: 68 | K4: 0 | L4: 68 | M4: 31 | N4: 37
A5: O00004 | B5: 45832 | C5: C0048 | D5: New | E5: West | F5: Organic Search | G5: Laptop Stand | H5: Home & Office | I5: 1 | J5: 38 | K5: 0.2 | L5: 30.4 | M5: 17 | N5: 13.4
A6: O00005 | B6: 45841 | C6: C0138 | D6: Returning | E6: Northeast | F6: Direct | G6: Insulated Bottle | H6: Lifestyle | I6: 2 | J6: 29 | K6: 0.1 | L6: 52.2 | M6: 22 | N6: 30.2
A7: O00006 | B7: 45698 | C7: C0093 | D7: Returning | E7: South | F7: Organic Search | G7: Travel Backpack | H7: Lifestyle | I7: 1 | J7: 68 | K7: 0.05 | L7: 64.6 | M7: 31 | N7: 33.6
A8: O00007 | B8: 45681 | C8: C0026 | D8: Returning | E8: West | F8: Email | G8: Desk Lamp | H8: Home & Office | I8: 2 | J8: 42 | K8: 0.2 | L8: 67.2 | M8: 38 | N8: 29.2
A9: O00008 | B9: 45890 | C9: C0019 | D9: Returning | E9: South | F9: Referral | G9: Insulated Bottle | H9: Lifestyle | I9: 1 | J9: 29 | K9: 0 | L9: 29 | M9: 11 | N9: 18
A10: O00009 | B10: 45783 | C10: C0143 | D10: Returning | E10: South | F10: Email | G10: Mechanical Keyboard | H10: Electronics | I10: 1 | J10: 89.99 | K10: 0 | L10: 89.99 | M10: 46 | N10: 43.99
A11: O00010 | B11: 45686 | C11: C0034 | D11: New | E11: South | F11: Referral | G11: Desk Lamp | H11: Home & Office | I11: 2 | J11: 42 | K11: 0.1 | L11: 75.6 | M11: 38 | N11: 37.6
A12: O00011 | B12: 45819 | C12: C0118 | D12: Returning | E12: South | F12: Email | G12: Desk Lamp | H12: Home & Office | I12: 2 | J12: 42 | K12: 0 | L12: 84 | M12: 38 | N12: 46
A13: O00012 | B13: 45729 | C13: C0110 | D13: Returning | E13: West | F13: Email | G13: Desk Lamp | H13: Home & Office | I13: 2 | J13: 42 | K13: 0.05 | L13: 79.8 | M13: 38 | N13: 41.8
... A1001: O01000 | B1001: 45731 | C1001: C0361 | D1001: New | E1001: Northeast | F1001: Paid Social | G1001: Travel Backpack | H1001: Lifestyle | I1001: 1 | J1001: 68 | K1001: 0.1 | L1001: 61.2 | M1001: 31 | N1001: 30.2
